{"priority": "minor", "kind": "bug", "repository": {"links": {"self": {"href": "data/repositories/osrf/gazebo.json"}, "html": {"href": "#!/osrf/gazebo"}, "avatar": {"href": "data/bytebucket.org/ravatar/{51a0cd5d-8697-4eb1-8b08-e919ee881e1c}ts=1694483"}}, "type": "repository", "name": "gazebo", "full_name": "osrf/gazebo", "uuid": "{51a0cd5d-8697-4eb1-8b08-e919ee881e1c}"}, "links": {"attachments": {"href": "data/repositories/osrf/gazebo/issues/2041/attachments_page=1.json"}, "self": {"href": "data/repositories/osrf/gazebo/issues/2041.json"}, "watch": {"href": "https://api.bitbucket.org/2.0/repositories/osrf/gazebo/issues/2041/watch"}, "comments": {"href": "data/repositories/osrf/gazebo/issues/2041/comments_page=1.json"}, "html": {"href": "#!/osrf/gazebo/issues/2041/integration_world_clone-test-may-timeout"}, "vote": {"href": "https://api.bitbucket.org/2.0/repositories/osrf/gazebo/issues/2041/vote"}}, "reporter": {"display_name": "Steve Peters", "uuid": "{2ccfed09-18b8-4921-8d58-15ef01092802}", "links": {"self": {"href": "https://api.bitbucket.org/2.0/users/%7B2ccfed09-18b8-4921-8d58-15ef01092802%7D"}, "html": {"href": "https://bitbucket.org/%7B2ccfed09-18b8-4921-8d58-15ef01092802%7D/"}, "avatar": {"href": "data/secure.gravatar.com/avatar/1fb4816dad9e68337d3096f750951f6cd=httpsavatar-management--avatars.us-west-2.prod.public.atl-paas.netinitialsSP-1.png"}}, "nickname": "Steven Peters", "type": "user", "account_id": "557058:5de38267-b118-494c-aa76-4fab35448816"}, "title": "INTEGRATION_world_clone test may timeout if system has other gzserver instances", "component": {"name": "testing", "links": {"self": {"href": "data/repositories/osrf/gazebo/components/128164.json"}}}, "votes": 0, "watches": 1, "content": {"raw": "I left a gazebo simulation running in a docker container while running my overnight testing script. The `INTEGRATION_world_clone` test failed via timeout many times. Each time, the `check_test_ran.py` script found a rogue gzserver that had been cloned but not killed. Also, I saw the following console message:\r\n\r\n~~~\r\n473: sh: 1: kill: Operation not permitted\r\n~~~\r\n\r\nI believe that the `Clone` test doesn't get the correct process id when [calling ps](#!/osrf/gazebo/src/bb6cc0893c9b6b160d46734c4fe9dbcbed1a1656/test/integration/world_clone.cc?fileviewer=file-view-default#world_clone.cc-219) since it just takes the first one given to it. It would be more robust to try to identify which is the correct `gzserver`.", "markup": "markdown", "html": "<p>I left a gazebo simulation running in a docker container while running my overnight testing script. The <code>INTEGRATION_world_clone</code> test failed via timeout many times. Each time, the <code>check_test_ran.py</code> script found a rogue gzserver that had been cloned but not killed. Also, I saw the following console message:</p>\n<div class=\"codehilite\"><pre><span></span><span class=\"mi\">473</span><span class=\"o\">:</span> <span class=\"n\">sh</span><span class=\"o\">:</span> <span class=\"mi\">1</span><span class=\"o\">:</span> <span class=\"n\">kill</span><span class=\"o\">:</span> <span class=\"n\">Operation</span> <span class=\"n\">not</span> <span class=\"n\">permitted</span>\n</pre></div>\n\n\n<p>I believe that the <code>Clone</code> test doesn't get the correct process id when <a data-is-external-link=\"true\" href=\"#!/osrf/gazebo/src/bb6cc0893c9b6b160d46734c4fe9dbcbed1a1656/test/integration/world_clone.cc?fileviewer=file-view-default#world_clone.cc-219\" rel=\"nofollow\">calling ps</a> since it just takes the first one given to it. It would be more robust to try to identify which is the correct <code>gzserver</code>.</p>", "type": "rendered"}, "assignee": null, "state": "new", "version": {"name": "all", "links": {"self": {"href": "data/repositories/osrf/gazebo/versions/225575.json"}}}, "edited_on": null, "created_on": "2016-09-01T01:01:21.507792+00:00", "milestone": null, "updated_on": "2016-09-14T19:19:58.594449+00:00", "type": "issue", "id": 2041}